Workbook

Sheet Calculations
A1: Scoring Criteria
A2: Score Type | B2: Score | E2: Special scoring for question types:
A3: 0 | B3: Wrong | E3: Negative Test (Q45-49): Score 2 only if chatbot says "not in document" or refuses to answer
A4: 1 | B4: Partial | E4: Trick Questions (Q50-54): Score 2 only if chatbot corrects the false premise
A5: 2 | B5: Correct | E5: Calculation (Q22-29): Score 2 only if final number/date is exactly right
A7: Accuracy Scores
A8: Type | B8: Count | C8: Accuracy | E8: Acceptable thresholds
A9: Descriptive | B9: 13 | C9: =(COUNTIFS('Golden Dataset'!$B:$B, "Descriptive", 'Golden Dataset'!$F:$F, "Correct")*2 + COUNTIFS('Golden Dataset'!$B:$B, "Descriptive", 'Golden Dataset'!$F:$F, "Partial")*1) / ($B9*2) -> 0.61538462 | E9: Overall: ≥85%
A10: Interpretative | B10: 8 | C10: =(COUNTIFS('Golden Dataset'!$B:$B, "Interpretative", 'Golden Dataset'!$F:$F, "Correct")*2 + COUNTIFS('Golden Dataset'!$B:$B, "Interpretative", 'Golden Dataset'!$F:$F, "Partial")*1) / ($B10*2) -> 0.875 | E10: Negative Tests: 100% (zero tolerance for hallucination)
A11: Calculation | B11: 8 | C11: =(COUNTIFS('Golden Dataset'!$B:$B, "Calculation", 'Golden Dataset'!$F:$F, "Correct")*2 + COUNTIFS('Golden Dataset'!$B:$B, "Calculation", 'Golden Dataset'!$F:$F, "Partial")*1) / ($B11*2) -> 0.625 | E11: Trick Questions: ≥80%
A12: Quantitative | B12: 8 | C12: =(COUNTIFS('Golden Dataset'!$B:$B, "Quantitative", 'Golden Dataset'!$F:$F, "Correct")*2 + COUNTIFS('Golden Dataset'!$B:$B, "Quantitative", 'Golden Dataset'!$F:$F, "Partial")*1) / ($B12*2) -> 0.5 | E12: Calculations: ≥80%
A13: Qualitative | B13: 7 | C13: =(COUNTIFS('Golden Dataset'!$B:$B, "Qualitative", 'Golden Dataset'!$F:$F, "Correct")*2 + COUNTIFS('Golden Dataset'!$B:$B, "Qualitative", 'Golden Dataset'!$F:$F, "Partial")*1) / ($B13*2) -> 0.71428571
A14: Negative Test (Critical for Hallucination) | B14: 5 | C14: =(COUNTIFS('Golden Dataset'!$B:$B, "Negative Test", 'Golden Dataset'!$F:$F, "Correct")*2 + COUNTIFS('Golden Dataset'!$B:$B, "Negative Test", 'Golden Dataset'!$F:$F, "Partial")*1) / ($B14*2) -> 1
A15: Trick Question (Critical for Contradiction Resistance) | B15: 5 | C15: =(COUNTIFS('Golden Dataset'!$B:$B, "Trick Question", 'Golden Dataset'!$F:$F, "Correct")*2 + COUNTIFS('Golden Dataset'!$B:$B, "Trick Question", 'Golden Dataset'!$F:$F, "Partial")*1) / ($B15*2) -> 0.2
A16: TOTAL | B16: 54 | C16: =(COUNTIF('Golden Dataset'!$F:$F, "Correct")*2 + COUNTIF('Golden Dataset'!$F:$F, "Partial")*1) / ($B16*2) -> 0.64814815
A18: Accuracy Formula = (2 * count of correct + 1 * count of partial) / (2 * Total questions count) * 100% | G18: =(COUNTIFS('Golden Dataset'!$B:$B, "Descriptive", 'Golden Dataset'!$F:$F, "Correct", 'Golden Dataset'!$A:$A, $A$23)*2 + COUNTIFS('Golden Dataset'!$B:$B, "Descriptive", 'Golden Dataset'!$F:$F, "Partial", 'Golden Dataset'!$A:$A, $A$23)*1) / ($B9*2) -> 0
A21: Historical Data (Accuracy Scores)
A22: Date | B22: Descriptive | C22: Interpretative | D22: Calculation | E22: Quantitative | F22: Qualitative | G22: Negative Test | H22: Trick Question | I22: Overall Score | J22: Change in Score (Overall)
A23: 46147 | B23: 0.84615385 | C23: 0.6875 | D23: 0.375 | E23: 0.5625 | F23: 0.78571429 | G23: 0.4 | H23: 0.8 | I23: 0.65740741 | J23: NA | K23: Qwen
A24: 46239 | B24: 0.46 | C24: 0.56 | D24: 0.88 | E24: 0.5 | F24: 0.57 | G24: 0.2 | H24: 0.2 | I24: 0.51 | J24: =I24-I23 -> -0.14740741 | K24: Llama | N24: Need to review prompt
A25: 18/5/2026 | B25: 0.81 | C25: 0.81 | D25: 0.88 | E25: 0.63 | F25: 0.57 | G25: 0.8 | H25: 0.6 | I25: 0.74 | J25: =I25-I24 -> 0.23
A26: 19/5/2026 | B26: 0.77 | C26: 0.69 | D26: 0.56 | E26: 0.56 | F26: 0.64 | G26: 0.8 | H26: 0.3 | I26: 0.64 | J26: =I26-I25 -> -0.1
A27: 26/05/2026 | B27: =C9 -> 0.61538462 | C27: =C10 -> 0.875 | D27: =C11 -> 0.625 | E27: =C12 -> 0.5 | F27: =C13 -> 0.71428571 | G27: =C14 -> 1 | H27: =C15 -> 0.2 | I27: =C16 -> 0.64814815 | J27: =I27-I26 -> 0.0081481481
A28: 46028 | B28: =C10 -> 0.875 | C28: =C11 -> 0.625 | D28: 0.69 | E28: 0.38 | F28: 0.5 | G28: 0.8 | H28: 0.3 | I28: 0.52 | J28: 0
A29: 46059 | B29: 0.62 | C29: 0.88 | D29: 0.63 | E29: 0.5 | F29: 0.71 | G29: 1 | H29: 0.2 | I29: 0.65 | J29: =I29-I28 -> 0.13

Sheet Golden Dataset
A1: 6 | B1: Question Type | C1: Question | D1: Ground Truth Answer | E1: Chatbot Answers | F1: Response Score Type | G1: Error Type (only for Partial & Wrong)
A2: 1 | B2: Descriptive | C2: List the six home health disciplines included in the 30-day period payment rate. | D2: 1. Skilled nursing services, 2. Home health aide services, 3. Physical therapy, 4. Speech-language pathology services, 5. Occupational therapy services, and 6. Medical social services. | E2: The six home health disciplines included in the 30-day period payment rate are: skilled nursing services (1), home health aide services (2), physical therapy (3), speech-language pathology services (4), occupational therapy services (5), and medical social services (6). | F2: Correct
A3: 2 | B3: Descriptive | C3: Which specific medical items are excluded from the 30-day period payment rate? | D3: Durable medical equipment (DME), certain injectable osteoporosis drugs for postmenopausal women with bone fractures, and disposable Negative Pressure Wound Therapy (dNPWT) devices. | E3: Durable medical equipment (DME) and certain injectable osteoporosis drugs, which are covered where a woman is postmenopausal and has a bone fracture, are excluded from the 30-day period payment rate (Medicare Policies p.0). | F3: Partial | G3: Partial retrieval
A4: 3 | B4: Descriptive | C4: What services are included in the 30-day period payment rate? | D4: All covered home health services, including the six home health disciplines (skilled nursing, home health aide, physical therapy, speech-language pathology, occupational therapy, medical social services) and routine/nonroutine medical supplies. | E4: The 30-day period payment rate includes costs for the six home health disciplines and the costs for routine and nonroutine medical supplies. The six home health disciplines included are skilled nursing services, home health aide services, physical therapy, speech-language pathology services, occupational therapy services, and medical social services (Home Health Policies p.0). | F4: Correct
A5: 4 | B5: Descriptive | C5: Who must bill for the excluded injectable osteoporosis drugs while a patient is under a home health plan of care? | D5: The home health agency (HHA) must bill for them due to consolidated billing requirements. | E5: The home health agency (HHA) must bill for the excluded injectable osteoporosis drugs while a patient is under a home health plan of care (medicare_policies.pdf p.0). | F5: Correct
A6: 5 | B6: Descriptive | C6: Does the separate payment for dNPWT include professional services? | D6: No, the payment covers only the disposable device (specified by HCPCS code) and does not include professional services. | E6: No, the separate payment for dNPWT does not include payment for professional services (Employee Handbook p.16). | F6: Correct
A7: 6 | B7: Descriptive | C7: What are the four case-mix variables obtained from home health or other Medicare claims? | D7: Admission Source (Institutional or Community), Timing (Early or Late), Clinical Group (one of 12), and Comorbidity Adjustment (none, low, high). | E7: The four case-mix variables obtained from home health or other Medicare claims are not explicitly stated in the provided documents. However, two variables are mentioned: Admission Source-Institutional (i.e., acute hospital, inpatient rehabilitation facility, skilled nursing facility, etc.) (Medicare Policies p.2) and Functional Impairment Level-As determined by responses to certain OASIS items (Medicare Policies p.1). The other two variables are not specified. | F7: Wrong | G7: Retrieval failure
A8: 7 | B8: Descriptive | C8: Which case-mix variable is derived from OASIS assessment responses? | D8: Functional Impairment Level (low, medium, high). | E8: The case-mix variable derived from OASIS assessment responses is the Functional Impairment Level, which is determined by responses to certain OASIS items (Employee Handbook p.8). | F8: Correct
A9: 8 | B9: Descriptive | C9: List all 12 Clinical Groups used in HH PPS case-mix. | D9: 1) Musculoskeletal Rehabilitation 2) Neuro/Stroke Rehabilitation 3) Wounds – Post-Op Wound Aftercare and Skin/Non-Surgical Wound Care 4) Behavioral Health Care 5) Complex Nursing Interventions 6) MMTA – Surgical Aftercare 7) MMTA – Cardiac/Circulatory 8) MMTA – Endocrine 9) MMTA – GI/GU 10) MMTA – Infectious Disease/Neoplasms/Blood-forming Diseases 11) MMTA – Respiratory 12) MMTA – Other | E9: The 12 Clinical Groups used in HH PPS case-mix are not explicitly listed in the provided documents. However, the primary reasons for the home health encounter are mentioned, which include: 1. Musculoskeletal Rehabilitation Therapy for a musculoskeletal condition (Musculoskeletal Rehabilitation) (p.1) 2. Neuro/Stroke Rehabilitation Therapy (physical, occupational, or speech) for a neurological condition or stroke (Neuro/Stroke Rehabilitation) (p.1) 3. | F9: Wrong | G9: Retrieval failure
A10: 9 | B10: Descriptive | C10: What is a Notice of Admission (NOA) and when did it replace RAPs? | D10: The NOA is a one-time submission that establishes a beneficiary is under a home health period of care and triggers consolidated billing edits. It replaced Requests for Anticipated Payment (RAPs) beginning January 1, 2022. | E10: A Notice of Admission (NOA) is a one-time submission to establish that a beneficiary is under a home health period of care and trigger home health consolidated billing edits. It covers contiguous 30-day periods of care until the individual is discharged. The NOA replaced Requests for Anticipated Payment (RAPs) beginning January 1, 2022 (Medicare Policies p.2). | F10: Correct
A11: 10 | B11: Descriptive | C11: What is the penalty for submitting an NOA late? | D11: Medicare reduces the payment for any period of care (including outlier payments) by the number of days from the home health admission date until the NOA submission date, divided by 30. No LUPA per-visit payments are made for visits that occurred before the NOA is submitted. The reduction is a provider liability and cannot be billed to the beneficiary. | E11: The penalty for submitting an NOA late is that Medicare shall reduce the payment for a period of care, including outlier payments, by the number of days from the home health admission date until the date the NOA is submitted to, and accepted by, the A/B MAC (HHH), divided by 30 (Medicare Policies p.2). | F11: Correct
A12: 11 | B12: Descriptive | C12: What exceptional circumstances does the document identify as potentially qualifying for a waiver of the untimely NOA penalty? | D12: 1) Fires, floods, earthquakes, or similar unusual events inflicting extensive damage on the HHA’s ability to operate. 2) A CMS or Medicare contractor systems issue beyond the HHA’s control. 3) A newly Medicare-certified HHA notified of certification after the Medicare certification date or awaiting its user ID from the contractor. 4) Other situations CMS determines to be beyond the HHA’s control. | E12: According to the document, exceptional circumstances that may qualify for a waiver of the untimely NOA penalty include fires, floods, earthquakes, or similar unusual events that inflict extensive damage to the home health agency's ability to operate (p.2). Additionally, a CMS or Medicare contractor systems issue that is beyond the control of the home health agency may also qualify (p.2). | F12: Partial | G12: Partial retrieval
A13: 12 | B13: Descriptive | C13: How are LUPA periods paid? | D13: They are paid the national per-visit amount by discipline, adjusted by the appropriate wage index, instead of the full 30-day period payment. | E13: LUPA periods are paid based on a payment group-specific threshold, which is the 10th percentile value of visits for each payment group. This threshold varies for a 30-day period of care, with a minimum threshold of at least 2 visits for each group (Medicare Policies p.3). If the number of visits is less than the LUPA threshold, the penalty is triggered (Medicare Policies p.2). | F13: Wrong | G13: Reasoning error
A14: 13 | B14: Descriptive | C14: How is the labor portion of the 30-day payment rate adjusted? | D14: By the pre-floor and pre-reclassified hospital wage index, based on the beneficiary’s site of service. | E14: I'm sorry, I was unable to find that information in the available documents. | F14: Wrong | G14: Retrieval failure
A15: 14 | B15: Interpretative | C15: Under what condition is a subsequent 30-day period of care classified as "Early" rather than "Late"? | D15: A subsequent period is "Early" only if there is a gap of more than 60 days between the end of one period of care and the start of another. | E15: A subsequent 30-day period of care is classified as Early rather than Late if there is a gap of more than 60 days between the end of one period of care and the start of another (Medicare Policies p.0). | F15: Correct
A16: 15 | B16: Interpretative | C16: Who bears the financial liability if a payment reduction occurs due to an untimely NOA filing? | D16: The reduction is a provider liability, and the home health agency (HHA) is prohibited from billing the beneficiary for it. | E16: The provider bears the financial liability if a payment reduction occurs due to an untimely NOA filing (Medicare Policies p.2). The provider shall not bill the beneficiary for this reduction (Medicare Policies p.2). | F16: Correct
A17: 16 | B17: Interpretative | C17: Does the 30-day payment rate for dNPWT include the professional services associated with the therapy? | D17: No, the separate payment for dNPWT includes only the device itself (specified by HCPCS code) and does not include payment for professional services. | E17: The 30-day period payment rate for nonroutine medical supplies and therapies, including dNPWT, does not explicitly include the professional services associated with the therapy (See §10.11.C for those services). | F17: Correct
A18: 17 | B18: Interpretative | C18: Can a 30-day period be assigned both a high comorbidity adjustment and a high functional impairment level? | D18: Yes, they are independent variables drawn from different sources (claims diagnoses and OASIS assessment, respectively). | E18: No, a 30-day period can be assigned a high comorbidity adjustment or a high functional impairment level, but not both. The case-mix variable is determined from responses to certain items on the OASIS assessment, and each 30-day period is assigned into one of 432 case-mix groups based on the variables described above (Medicare Policies p.1). | F18: Wrong | G18: Reasoning error
A19: 18 | B19: Interpretative | C19: A 30-day period has only 2 visits while its payment group’s LUPA threshold is 3. How is this period paid? | D19: It is paid per-visit: the HHA receives the national wage-adjusted per-visit amount for each discipline rendered; the full 30-day period payment is not made because visits (2) fall below the payment group's LUPA threshold (3). | E19: For a 30-day period with only 2 visits, when the payment group's LUPA threshold is 3, the period is paid the wage-adjusted per visit amount for each of the visits rendered instead of the full 30-day period payment amount (LUPA Policy p.3). | F19: Correct
A20: 19 | B20: Interpretative | C20: Why does the case-mix methodology use both claims data and OASIS data? | D20: Claims data provides admission source, timing, clinical group, and comorbidity information, while OASIS provides functional impairment level data; together they enable accurate grouping into 432 case-mix groups that reflect relative resource needs. | E20: The case-mix methodology uses both claims data and OASIS data to group 30-day periods of care into their case-mix groups, as these variables provide a comprehensive understanding of the patient's needs and resource requirements (Medicare Policies p.0). Claims data and OASIS data are used together to ensure accurate and reliable case-mix grouping (Medicare Policies p.0). | F20: Correct
A21: 20 | B21: Interpretative | C21: Why is the LUPA payment increased by an add-on amount for some LUPAs? | D21: To offset the full cost of longer, initial visits in some LUPA periods, as stated in the policy. | E21: The LUPA payment is increased by an add-on amount for LUPAs that occur as the on-site visit exceeds the normal visit duration, specifically for longer, initial visits in some LUPA periods (Medicare Policies p.3). | F21: Correct
A22: 21 | B22: Interpretative | C22: What does it mean that the NOA covers "contiguous" 30-day periods? | D22: The NOA covers contiguous (consecutive, unbroken) 30-day periods of care until the individual is discharged from Medicare home health services. A single NOA submission is sufficient for all such periods. | E22: The NOA (Notice of Admission) covers contiguous 30-day periods of care until the individual is discharged from Medicare home health services (Employee Handbook p.2). | F22: Correct
A23: 22 | B23: Calculation | C23: If a patient is admitted on January 1st, what is the latest date the NOA can be submitted to be considered "timely-filed"? | D23: The NOA must be submitted on or before January 6th (within 5 calendar days from the start of care). | E23: According to the Medicare policies, if a patient is admitted on January 1st, the NOA would be considered timely-filed if it is submitted on or before January 6th (Day 5 of the first 30-day period of care) (Medicare policies p.2). | F23: Correct
A24: 23 | B24: Calculation | C24: How is the penalty calculated for a 30-day period of care when the NOA is submitted late? | D24: The payment (including outliers) is reduced by the number of days from the admission date until the date the NOA is submitted and accepted, divided by 30. | E24: When the Notice of Admission (NOA) is submitted late, Medicare shall reduce the payment for the 30-day period of care by adjusting the payment rate based on a case-mix methodology (Employee Handbook p.2). The payment rate is adjusted by a case-mix methodology based on information from home health claims, other Medicare claims, and data elements from the Outcome and Assessment Information Set (OASIS) (Employee Handbook p.2). | F24: Wrong | G24: Reasoning error
A25: 24 | B25: Calculation | C25: On which days of an initial 60-day certification period must a recertification assessment be performed? | D25: The assessment must be done during the last 5 days of the period, which are days 56 through 60. | E25: I'm sorry, I was unable to find that information in the available documents. | F25: Wrong | G25: Retrieval failure
A26: 25 | B26: Calculation | C26: If an NOA is submitted 15 days after the admission date, what fraction is used to reduce the payment for that period? | D26: The reduction is calculated as 15 divided by 30 (or 50% of the payment). | E26: To calculate the payment reduction, the number of days from the home health admission date until the date the NOA is submitted and accepted by the A/B MAC is divided by 30. In this case, the number of days is 15. So, the fraction used to reduce the payment is 15/30, which simplifies to 1/2 (Employee Handbook not provided, but calculation based on Medicare Policies p.2). | F26: Correct
A27: 26 | B27: Calculation | C27: A payment group’s 10th percentile of visits is 1. What is the LUPA threshold for that group? | D27: The minimum threshold is 2 visits, so the LUPA threshold is 2. | E27: Unfortunately, the provided documents do not explicitly state how to calculate the LUPA threshold for a specific payment group. However, it does mention that the LUPA threshold is used to determine payment, but the exact calculation method is not specified. | F27: Wrong | G27: Reasoning error
A28: 27 | B28: Calculation | C28: If a patient has visits on days 1, 15, and 20 of a 30-day period, and the payment group's LUPA threshold is 4, how is the period paid? | D28: As a LUPA — paid the wage-adjusted national per visit amount for each of the 3 visits rendered, since 3 < 4. | E28: Therefore, the period is paid the wage-adjusted per visit amount for each of the visits rendered instead of the full 30-day period payment amount (medicare_plicies.pdf p.3). | F28: Correct
A29: 28 | B29: Calculation | C29: How many 30-day payment periods are included in three continuous 60-day recertifications? | D29: Six. Each 60-day certification includes two 30-day payment periods; 3 × 2 = 6. | E29: "Three continuous 60-day recertifications can include a total of six 30-day payment periods. Each 60-day certification can include two 30-day payment periods (Medicare Policies p.2)." | F29: Correct
A30: 29 | B30: Calculation | C30: How many total case-mix groups are possible given: 2 admission sources × 2 timing values × 12 clinical groups × 3 comorbidity levels × 3 functional levels? | D30: 432. 2 × 2 × 12 × 3 × 3 = 432. | E30: "To determine the total number of case-mix groups, we multiply the number of options for each variable: 2 admission sources × 2 timing values × 12 clinical groups × 3 comorbidity levels × 3 functional levels. This calculation results in 2 × 2 × 12 × 3 × 3 = 432 case-mix groups." | F30: Correct
A31: 30 | B31: Quantitative | C31: Into how many clinical groups are 30-day periods assigned based on the primary reason for the encounter? | D31: There are 12 clinical groups. | E31: "30-day periods are assigned to one of 12 clinical groups describing the primary reason for the home health encounter (Clinical Groups)." | F31: Correct
A32: 31 | B32: Quantitative | C32: What is the total number of case-mix groups available for assigning a 30-day period? | D32: Each 30-day period is assigned into one of 432 case-mix groups. | E32: "According to the Medicare Policies document, there are 12 clinical groups describing the primary reason for the home health encounter (Clinical Groups The Primary Reason for the Home Health Encounter is to Provide..). Additionally, the document mentions that the 30-day period payment rate is adjusted by a case-mix methodology based on information from home health claims, other Medicare claims, and data elements from the Outcome and Assessment Information Set (OASIS), which groups 30-day periods of care into their case-mix groups. However, the total number of case-mix groups is not explicitly stated in the provided documents." | F32: Partial | G32: Reasoning error
A33: 32 | B33: Quantitative | C33: What is the minimum possible threshold for a Low Utilization Payment Adjustment (LUPA)? | D33: The minimum LUPA threshold is at least 2 visits for each payment group. | E33: "The minimum possible threshold for a Low Utilization Payment Adjustment (LUPA) is at least 2 visits for each payment group (LUPA threshold with a 10th percentile value of visits) (Medicare Policies p.3)." | F33: Correct
A34: 33 | B34: Quantitative | C34: A recertification assessment must be performed during which days of the previous certification period? | D34: The last 5 days (days 56–60 of a 60‑day certification). | E34: "According to the Medicare policies, the recertification assessment must be done during the last 5 days of the previous certification period (Employee Handbook 2025 - Copy.pdf p.15, citing 42 CFR 484.55(d)(1))." | F34: Correct
A35: 34 | B35: Quantitative | C35: What is the maximum gap (in days) between two 30‑day periods that keeps the Timing classification as “Late”? | D35: 60 days or fewer; a gap of more than 60 days resets the next period to “Early.” | E35: "I'm sorry, I was unable to find that information in the available documents." | F35: Wrong | G35: Retrieval failure
A36: 35 | B36: Quantitative | C36: What percentile of visits is used to set the LUPA threshold? | D36: The 10th percentile. | E36: "Unfortunately, the available documents do not specify the percentile of visits used to set the LUPA threshold." | F36: Wrong | G36: Retrieval failure
A37: 36 | B37: Quantitative | C37: How many case-mix variables come from claims data? | D37: Four: Admission Source, Timing, Clinical Group, and Comorbidity Adjustment. | E37: "There are two case-mix variables obtained from home health or other Medicare claims: Admission Source-Institutional (p.2) and Comorbidity Adjustment (p.1)." | F37: Partial | G37: Partial retrieval
A38: 37 | B38: Quantitative | C38: How many case-mix variables come from OASIS data? | D38: One: Functional Impairment Level. | E38: "There are two case-mix variables obtained from OASIS data: Functional Impairment Level and Admission Source (p.1 of medicare_plicies.pdf)." | F38: Wrong | G38: Hallucination
A39: 38 | B39: Qualitative | C39: What qualifies as an 'exceptional circumstance' that might allow CMS to waive the penalty for a late NOA? | D39: Events such as fires, floods, or earthquakes; CMS or contractor systems issues; or delays in receiving Medicare certification that are beyond the HHA's control. | E39: "According to the Medicare policies, an exceptional circumstance may be due to, but is not limited to, fires, floods, earthquakes, or similar unusual events that inflict extensive damage to the home health agency's ability to operate (Medicare policies p.2). Additionally, a CMS or Medicare contractor systems issue that is beyond the control of the home health agency may also qualify as an exceptional circumstance (Medicare policies p.2)." | F39: Correct
A40: 39 | B40: Qualitative | C40: What are the three levels of Functional Impairment used for case-mix assignment? | D40: The levels are Low, Medium, and High. | E40: "The three levels of Functional Impairment used for case-mix assignment are low, medium, and high. (Employee Handbook p.22 is not available in the context, however, the information is available on p.1 of medicare_plicies.pdf)" | F40: Correct
...

Sheet Golden Dataset-1
A1: 6 | B1: Question Type | C1: Question | D1: Ground Truth Answer | E1: Chatbot Answers | F1: Response Score Type | G1: Error Type (only for Partial & Wrong)
A2: 1 | B2: Descriptive | C2: List the six home health disciplines included in the 30-day period payment rate. | D2: 1. Skilled nursing services, 2. Home health aide services, 3. Physical therapy, 4. Speech-language pathology services, 5. Occupational therapy services, and 6. Medical social services. | E2: \n────────────────────────────────────────────────────────────\n Answer\n────────────────────────────────────────────────────────────\n The six home health disciplines included in the 30-day period payment rate are skilled nursing services, home health\n\n 📄 Sources\n────────────────────────────────────────────────────────────\n medicare_plicies.pdf (p.0) – Link not available\n medicare_plicies.pdf (p.3) – Link not available\n medicare_plicies.pdf (p.2) – Link not available\n\n 📊 Confidence: 97% | ⏱ 10.63s\n──────────────────────────────────────────────────────────── | F2: Wrong | G2: Partial retrieval
A3: 2 | B3: Descriptive | C3: Which specific medical items are excluded from the 30-day period payment rate? | D3: Durable medical equipment (DME), certain injectable osteoporosis drugs for postmenopausal women with bone fractures, and disposable Negative Pressure Wound Therapy (dNPWT) devices. | E3: \n────────────────────────────────────────────────────────────\n Answer\n────────────────────────────────────────────────────────────\n Certain injectable osteoporosis drugs which are covered where a woman is postmenopausal and has a bone fracture are also excluded from the 30-day period payment rate. Answer: The 30-day period payment rate also excludes amounts for nonroutine medical supplies and therapies that could have been unbundled to Part B prior to HH PPS. Answer: The\n\n 📄 Sources\n────────────────────────────────────────────────────────────\n medicare_plicies.pdf (p.0) – Link not available\n medicare_plicies.pdf (p.3) – Link not available\n\n 📊 Confidence: 97% | ⏱ 10.845s\n────────────────────────────────────────────────────────────", | F3: Partial | G3: Partial retrieval
A4: 3 | B4: Descriptive | C4: What services are included in the 30-day period payment rate? | D4: All covered home health services, including the six home health disciplines (skilled nursing, home health aide, physical therapy, speech-language pathology, occupational therapy, medical social services) and routine/nonroutine medical supplies. | E4: \n────────────────────────────────────────────────────────────\n Answer\n────────────────────────────────────────────────────────────\n The 30-day period payment rate includes all covered home health services, including medical supplies, paid on a reasonable cost basis (A. Services Included, 10.1 National 30-Day Period Payment Rate, Medicare Policies p.0).\n\n 📄 Sources\n────────────────────────────────────────────────────────────\n medicare_plicies.pdf (p.0) – Link not available\n medicare_plicies.pdf (p.3) – Link not available\n Elumina Health Employee Handbook 2025 - Copy.pdf (p.30) – https://drive.google.com/mock-handbook-link\n\n 📊 Confidence: 97% | ⏱ 10.633s\n────────────────────────────────────────────────────────────", | F4: Wrong | G4: Retrieval failure
A5: 4 | B5: Descriptive | C5: Who must bill for the excluded injectable osteoporosis drugs while a patient is under a home health plan of care? | D5: The home health agency (HHA) must bill for them due to consolidated billing requirements. | E5: \n────────────────────────────────────────────────────────────\n Answer\n────────────────────────────────────────────────────────────\n The home health agency (HHA) must bill for the excluded injectable osteoporosis drugs while a patient is under a home health plan of care (medicare_plicies.pdf p.0).\n\n 📄 Sources\n────────────────────────────────────────────────────────────\n medicare_plicies.pdf (p.0) – Link not available\n medicare_plicies.pdf (p.2) – Link not available\n Elumina Health Employee Handbook 2025 - Copy.pdf (p.15) – https://drive.google.com/mock-handbook-link\n\n 📊 Confidence: 97% | ⏱ 10.852s\n────────────────────────────────────────────────────────────", | F5: Correct
A6: 5 | B6: Descriptive | C6: Does the separate payment for dNPWT include professional services? | D6: No, the payment covers only the disposable device (specified by HCPCS code) and does not include professional services. | E6: "\n────────────────────────────────────────────────────────────\n Answer\n────────────────────────────────────────────────────────────\n According to the Medicare policies, the separate payment for dNPWT does not include payment for professional services (Medicare policies p.0). The payment only includes the device paid separately, as specified by the assigned HCPCS code.\n\n 📄 Sources\n────────────────────────────────────────────────────────────\n medicare_plicies.pdf (p.0) – Link not available\n medicare_plicies.pdf (p.2) – Link not available\n Elumina Health Employee Handbook 2025 - Copy.pdf (p.11) – https://drive.google.com/mock-handbook-link\n Elumina Health Employee Handbook 2025 - Copy.pdf (p.16) – https://drive.google.com/mock-handbook-link\n medicare_plicies.pdf (p.3) – Link not available\n Elumina Health Employee Handbook 2025 - Copy.pdf (p.7) – https://drive.google.com/mock-handbook-link\n\n 📊 Confidence: 97% | ⏱ 10.981s\n────────────────────────────────────────────────────────────" | F6: Correct
A7: 6 | B7: Descriptive | C7: What are the four case-mix variables obtained from home health or other Medicare claims? | D7: Admission Source (Institutional or Community), Timing (Early or Late), Clinical Group (one of 12), and Comorbidity Adjustment (none, low, high). | E7: "\n────────────────────────────────────────────────────────────\n Answer\n────────────────────────────────────────────────────────────\n The four case-mix variables obtained from home health or other Medicare claims are: Admission Source-Institutional, Comorbidity Adjustment, Functional Impairment Level. Source: [medicare_plicies.pdf p.0] and [medicare_plicies.pdf p\n\n 📄 Sources\n────────────────────────────────────────────────────────────\n medicare_plicies.pdf (p.0) – Link not available\n medicare_plicies.pdf (p.1) – Link not available\n medicare_plicies.pdf (p.2) – Link not available\n\n 📊 Confidence: 97% | ⏱ 10.881s\n────────────────────────────────────────────────────────────" | F7: Partial | G7: Partial retrieval
A8: 7 | B8: Descriptive | C8: Which case-mix variable is derived from OASIS assessment responses? | D8: Functional Impairment Level (low, medium, high). | E8: "\n────────────────────────────────────────────────────────────\n Answer\n────────────────────────────────────────────────────────────\n The case-mix variable is determined from responses to certain items on the OASIS assessment, specifically the Functional Impairment Level-As determined by responses to certain OASIS items. (Employee Handbook p.8) cites the CMS policies on the communication of patient identifiable information. However, the specific case-mix variable derived from OASIS assessment responses is the Functional Impairment Level. (medicare_plicies.pdf p.1) Each 30-day period of care can be assigned a low, medium, or high functional impairment level.\n\n 📄 Sources\n────────────────────────────────────────────────────────────\n medicare_plicies.pdf (p.1) – Link not available\n medicare_plicies.pdf (p.0) – Link not available\n Elumina Health Employee Handbook 2025 - Copy.pdf (p.8) – https://drive.google.com/mock-handbook-link\n medicare_plicies.pdf (p.2) – Link not available\n Elumina Health Employee Handbook 2025 - Copy.pdf (p.29) – https://drive.google.com/mock-handbook-link\n\n 📊 Confidence: 97% | ⏱ 10.918s\n────────────────────────────────────────────────────────────" | F8: Correct
A9: 8 | B9: Descriptive | C9: List all 12 Clinical Groups used in HH PPS case-mix. | D9: 1) Musculoskeletal Rehabilitation 2) Neuro/Stroke Rehabilitation 3) Wounds – Post-Op Wound Aftercare and Skin/Non-Surgical Wound Care 4) Behavioral Health Care 5) Complex Nursing Interventions 6) MMTA – Surgical Aftercare 7) MMTA – Cardiac/Circulatory 8) MMTA – Endocrine 9) MMTA – GI/GU 10) MMTA – Infectious Disease/Neoplasms/Blood-forming Diseases 11) MMTA – Respiratory 12) MMTA – Other | E9: "\n────────────────────────────────────────────────────────────\n Answer\n────────────────────────────────────────────────────────────\n The 12 Clinical Groups used in HH PPS case-mix are: Musculoskeletal Rehabilitation Therapy, Neuro/Stroke Rehabilitation Therapy, Wounds – Post-Op Wound Aftercare and Skin/Non-Surgical Wound Care Assessment, treatment & evaluation of a surgical wound(s); assessment, treatment and evaluation of a non-surgical wound(s), Cardiac Care, Respiratory Care, Congestive Heart Failure, Chronic Obstructive Pulmonary Disease, Gastrointestinal Disorders, Hemiplegia, Psychiatric, and Cancer.\n\n 📄 Sources\n────────────────────────────────────────────────────────────\n medicare_plicies.pdf (p.1) – Link not available\n medicare_plicies.pdf (p.0) – Link not available\n medicare_plicies.pdf (p.2) – Link not available\n Policy C-901 Unacceptable Abbreviations (1).pdf (p.0) – https://drive.google.com/mock-abbreviation-link\n Elumina Health Employee Handbook 2025 - Copy.pdf (p.7) – https://drive.google.com/mock-handbook-link\n\n 📊 Confidence: 92% | ⏱ 9.55s\n────────────────────────────────────────────────────────────" | F9: Partial | G9: Partial retrieval
A10: 9 | B10: Descriptive | C10: What is a Notice of Admission (NOA) and when did it replace RAPs? | D10: The NOA is a one-time submission that establishes a beneficiary is under a home health period of care and triggers consolidated billing edits. It replaced Requests for Anticipated Payment (RAPs) beginning January 1, 2022. | E10: "\n────────────────────────────────────────────────────────────\n Answer\n────────────────────────────────────────────────────────────\n The NOA covers contiguous 30-day periods of care until the individual is discharged from home health care (Medicare Policies p.2). Employee Question: What are the requirements for submission of the NOA? Answer: For CY 2022, submission of the NOA can be made when the following criteria have been met: (1) the appropriate physician’s or allowed practitioner’s written or verbal order that sets out the services required for the initial visit has been received and documented as required at §§ 484.60(b) and 409.43(d); (2) the initial visit within the 60-day certification period must have been made and the individual admitted to home health\n\n 📄 Sources\n────────────────────────────────────────────────────────────\n medicare_plicies.pdf (p.2) – Link not available\n medicare_plicies.pdf (p.3) – Link not available\n Elumina Health Employee Handbook 2025 - Copy.pdf (p.12) – https://drive.google.com/mock-handbook-link\n Elumina Health Employee Handbook 2025 - Copy.pdf (p.16) – https://drive.google.com/mock-handbook-link\n medicare_plicies.pdf (p.0) – Link not available\n Elumina Health Employee Handbook 2025 - Copy.pdf (p.13) – https://drive.google.com/mock-handbook-link\n\n 📊 Confidence: 97% | ⏱ 11.0s\n────────────────────────────────────────────────────────────", | F10: Wrong | G10: Reasoning error
A11: 10 | B11: Descriptive | C11: What is the penalty for submitting an NOA late? | D11: Medicare reduces the payment for any period of care (including outlier payments) by the number of days from the home health admission date until the NOA submission date, divided by 30. No LUPA per-visit payments are made for visits that occurred before the NOA is submitted. The reduction is a provider liability and cannot be billed to the beneficiary. | E11: "\n────────────────────────────────────────────────────────────\n Answer\n────────────────────────────────────────────────────────────\n According to the Medicare policies, if an NOA is submitted on or after Day 6 (January 7, 2022\n\n 📄 Sources\n────────────────────────────────────────────────────────────\n medicare_plicies.pdf (p.2) – Link not available\n Elumina Health Employee Handbook 2025 - Copy.pdf (p.29) – https://drive.google.com/mock-handbook-link\n Elumina Health Employee Handbook 2025 - Copy.pdf (p.18) – https://drive.google.com/mock-handbook-link\n\n 📊 Confidence: 97% | ⏱ 10.802s\n────────────────────────────────────────────────────────────" | F11: Wrong | G11: Reasoning error
A12: 11 | B12: Descriptive | C12: What exceptional circumstances does the document identify as potentially qualifying for a waiver of the untimely NOA penalty? | D12: 1) Fires, floods, earthquakes, or similar unusual events inflicting extensive damage on the HHA’s ability to operate. 2) A CMS or Medicare contractor systems issue beyond the HHA’s control. 3) A newly Medicare-certified HHA notified of certification after the Medicare certification date or awaiting its user ID from the contractor. 4) Other situations CMS determines to be beyond the HHA’s control. | E12: "\n────────────────────────────────────────────────────────────\n Answer\n────────────────────────────────────────────────────────────\n According to the Medicare policies (p.2), exceptional circumstances that may qualify for a waiver of the untimely NOA penalty include, but are not limited to, fires, floods, earthquakes, or similar unusual events that inflict extensive damage to the home health agency's ability to operate, and a CMS or Medicare contractor systems issue that is beyond the control of the home health agency.\n\n 📄 Sources\n────────────────────────────────────────────────────────────\n medicare_plicies.pdf (p.2) – Link not available\n Elumina Health Employee Handbook 2025 - Copy.pdf (p.3) – https://drive.google.com/mock-handbook-link\n\n 📊 Confidence: 87% | ⏱ 6.436s\n────────────────────────────────────────────────────────────", | F12: Partial | G12: Partial retrieval
A13: 12 | B13: Descriptive | C13: How are LUPA periods paid? | D13: They are paid the national per-visit amount by discipline, adjusted by the appropriate wage index, instead of the full 30-day period payment. | E13: "\n────────────────────────────────────────────────────────────\n Answer\n────────────────────────────────────────────────────────────\n The LUPA threshold varies for a 30-day period of care depending on the payment group to which it is assigned (Medicare Policies p.3). A 30-day period with visits less than the LUPA threshold for each group is required to be done on days 56-60 (Medicare Policies p.2). The LUPA threshold is a payment group-specific value with a minimum threshold of at least 2 visits for each group (Medicare Policies p.3). The LUPA threshold is used to create a payment group-specific LUPA threshold with a minimum threshold of at least 2 visits for each group .\n\n 📄 Sources\n────────────────────────────────────────────────────────────\n medicare_plicies.pdf (p.3) – Link not available\n medicare_plicies.pdf (p.2) – Link not available\n Elumina Health Employee Handbook 2025 - Copy.pdf (p.3) – https://drive.google.com/mock-handbook-link\n Elumina Health Employee Handbook 2025 - Copy.pdf (p.9) – https://drive.google.com/mock-handbook-link\n Elumina Health Employee Handbook 2025 - Copy.pdf (p.22) – https://drive.google.com/mock-handbook-link\n\n 📊 Confidence: 97% | ⏱ 13.234s\n────────────────────────────────────────────────────────────", | F13: Wrong | G13: Reasoning error
A14: 13 | B14: Descriptive | C14: How is the labor portion of the 30-day payment rate adjusted? | D14: By the pre-floor and pre-reclassified hospital wage index, based on the beneficiary’s site of service. | E14: "\n────────────────────────────────────────────────────────────\n Answer\n────────────────────────────────────────────────────────────\n The labor portion of the 30-day payment rate is adjusted to reflect the wage index based on the site of service of the beneficiary. (Labor Adjustments p.1) The beneficiary's location is the determining factor for the labor adjustment. (Labor Adjustments p.1) The HH PPS rates are adjusted by the pre floor and pre-reclassified hospital wage index. The hospital wage index is adjusted to account for the geographic reclassification of hospitals in accordance with the Social Security Act.\n\n 📄 Sources\n────────────────────────────────────────────────────────────\n medicare_plicies.pdf (p.1) – Link not available\n medicare_plicies.pdf (p.0) – Link not available\n medicare_plicies.pdf (p.3) – Link not available\n\n 📊 Confidence: 97% | ⏱ 10.63s\n────────────────────────────────────────────────────────────", | F14: Correct
A15: 14 | B15: Interpretative | C15: Under what condition is a subsequent 30-day period of care classified as "Early" rather than "Late"? | D15: A subsequent period is "Early" only if there is a gap of more than 60 days between the end of one period of care and the start of another. | E15: "\n────────────────────────────────────────────────────────────\n Answer\n────────────────────────────────────────────────────────────\n Answer: A subsequent 30-day period of care is classified as Early rather than Late if there is a gap of more than 60 days between the end of one period of care and the start of another. (Medicare Policies p.0) Answer: A subsequent 30-day period of care is classified as Early rather than Late if there is a gap of more than 60 days between the end of one\n\n 📄 Sources\n────────────────────────────────────────────────────────────\n medicare_plicies.pdf (p.0) – Link not available\n medicare_plicies.pdf (p.2) – Link not available\n medicare_plicies.pdf (p.3) – Link not available\n medicare_plicies.pdf (p.1) – Link not available\n\n 📊 Confidence: 95% | ⏱ 10.947s\n────────────────────────────────────────────────────────────", | F15: Correct
A16: 15 | B16: Interpretative | C16: Who bears the financial liability if a payment reduction occurs due to an untimely NOA filing? | D16: The reduction is a provider liability, and the home health agency (HHA) is prohibited from billing the beneficiary for it. | E16: "\n────────────────────────────────────────────────────────────\n Answer\n────────────────────────────────────────────────────────────\n The provider bears the financial liability if a payment reduction occurs due to an untimely NOA filing (Medicare Policies p.2). The provider shall not bill the beneficiary for it (Medicare Policies p.2). This reduction shall be a provider liability .\n\n 📄 Sources\n────────────────────────────────────────────────────────────\n medicare_plicies.pdf (p.2) – Link not available\n Elumina Health Employee Handbook 2025 - Copy.pdf (p.10) – https://drive.google.com/mock-handbook-link\n Elumina Health Employee Handbook 2025 - Copy.pdf (p.26) – https://drive.google.com/mock-handbook-link\n\n 📊 Confidence: 74% | ⏱ 10.773s\n────────────────────────────────────────────────────────────" | F16: Partial | G16: Partial retrieval
A17: 16 | B17: Interpretative | C17: Does the 30-day payment rate for dNPWT include the professional services associated with the therapy? | D17: No, the separate payment for dNPWT includes only the device itself (specified by HCPCS code) and does not include payment for professional services. | E17: "\n────────────────────────────────────────────────────────────\n Answer\n────────────────────────────────────────────────────────────\n No, the 30-day payment rate for dNPWT does not include payment for the professional services (Employee Handbook p.0). I'm sorry, I\n\n 📄 Sources\n────────────────────────────────────────────────────────────\n medicare_plicies.pdf (p.0) – Link not available\n medicare_plicies.pdf (p.2) – Link not available\n medicare_plicies.pdf (p.3) – Link not available\n\n 📊 Confidence: 92% | ⏱ 10.718s\n────────────────────────────────────────────────────────────" | F17: Correct
A18: 17 | B18: Interpretative | C18: Can a 30-day period be assigned both a high comorbidity adjustment and a high functional impairment level? | D18: Yes, they are independent variables drawn from different sources (claims diagnoses and OASIS assessment, respectively). | E18: "\n────────────────────────────────────────────────────────────\n Answer\n────────────────────────────────────────────────────────────\n According to the case-mix methodology, a 30-day period can be assigned a high comorbidity adjustment, a low comorbidity adjustment, or a high comorbidity adjustment (Medicare Policies p.1). Additionally, a 30-day period can be assigned a low, medium, or high functional impairment level (Medicare Policies p.1). However, there is no information provided that indicates a 30-day period can be assigned both a high comorbidity adjustment and a high functional impairment level simultaneously. I'm sorry, I was unable to find that information in the available documents.\n\n 📄 Sources\n────────────────────────────────────────────────────────────\n medicare_plicies.pdf (p.1) – Link not available\n medicare_plicies.pdf (p.0) – Link not available\n medicare_plicies.pdf (p.3) – Link not available\n Elumina Health Employee Handbook 2025 - Copy.pdf (p.29) – https://drive.google.com/mock-handbook-link\n Elumina Health Employee Handbook 2025 - Copy.pdf (p.7) – https://drive.google.com/mock-handbook-link\n\n 📊 Confidence: 0% | ⏱ 11.325s\n────────────────────────────────────────────────────────────\n\n ⚠️ This answer may be incomplete. For further assistance, please reach out to:\n Greg Smith | greg@company.com | +1-555-123-4567" | F18: Wrong | G18: Reasoning error
A19: 18 | B19: Interpretative | C19: A 30-day period has only 2 visits while its payment group’s LUPA threshold is 3. How is this period paid? | D19: It is paid per-visit: the HHA receives the national wage-adjusted per-visit amount for each discipline rendered; the full 30-day period payment is not made because visits (2) fall below the payment group's LUPA threshold (3). | E19: "\n────────────────────────────────────────────────────────────\n Answer\n────────────────────────────────────────────────────────────\n This 30-day period would receive no comorbidity adjustment (Medicare Policies p.1). The payment for this period would be reduced by the number of days from the home health admission date until the date the NOA is submitted to, and accepted by, the A/B MAC (HHH), divided by 30 (Medicare Policies p.2). No LUPA per-visit payments shall be made for visits that occurred on days that fall within the period of care prior to the submission of the NOA (Medicare Policies p.2). The provider shall not bill the beneficiary for this reduction .\n\n 📄 Sources\n────────────────────────────────────────────────────────────\n medicare_plicies.pdf (p.3) – Link not available\n medicare_plicies.pdf (p.1) – Link not available\n medicare_plicies.pdf (p.0) – Link not available\n medicare_plicies.pdf (p.2) – Link not available\n\n 📊 Confidence: 97% | ⏱ 10.684s\n────────────────────────────────────────────────────────────" | F19: Wrong | G19: Hallucination
A20: 19 | B20: Interpretative | C20: Why does the case-mix methodology use both claims data and OASIS data? | D20: Claims data provides admission source, timing, clinical group, and comorbidity information, while OASIS provides functional impairment level data; together they enable accurate grouping into 432 case-mix groups that reflect relative resource needs. | E20: "\n────────────────────────────────────────────────────────────\n Answer\n────────────────────────────────────────────────────────────\n Discussing information concerning other patients with anyone, including the patient, family, or other staff, is not allowed while caring for a patient, as stated in the Employee Handbook (p.8). This is for privacy and security reasons, and communication of OASIS information will be done in accordance with CMS policies on the communication of patient identifiable information. (Employee Handbook p.8) Employee Question: What is the purpose of using secure passwords for data encoding and transmission? Answer: The purpose\n\n 📄 Sources\n────────────────────────────────────────────────────────────\n medicare_plicies.pdf (p.0) – Link not available\n Elumina Health Employee Handbook 2025 - Copy.pdf (p.8) – https://drive.google.com/mock-handbook-link\n medicare_plicies.pdf (p.1) – Link not available\n Elumina Health Employee Handbook 2025 - Copy.pdf (p.14) – https://drive.google.com/mock-handbook-link\n Elumina Health Employee Handbook 2025 - Copy.pdf (p.3) – https://drive.google.com/mock-handbook-link\n\n 📊 Confidence: 97% | ⏱ 10.677s\n────────────────────────────────────────────────────────────" | F20: Wrong | G20: Hallucination
A21: 20 | B21: Interpretative | C21: Why is the LUPA payment increased by an add-on amount for some LUPAs? | D21: To offset the full cost of longer, initial visits in some LUPA periods, as stated in the policy. | E21: "\n────────────────────────────────────────────────────────────\n Answer\n────────────────────────────────────────────────────────────\n The LUPA payment is increased by an add-on amount for LUPAs that occur as the onset of a longer, initial visit in some LUPA periods (Medicare Policies p.3). Answer: The LUPA payment is increased by an add-on amount for LUPAs that occur as the onset of a longer, initial visit in some LUPA periods (Medicare Policies p.3). Answer: The LUPA payment is increased by an add-on amount for LUPAs that occur as the onset of a longer, initial visit\n\n 📄 Sources\n────────────────────────────────────────────────────────────\n medicare_plicies.pdf (p.3) – Link not available\n medicare_plicies.pdf (p.2) – Link not available\n Elumina Health Employee Handbook 2025 - Copy.pdf (p.23) – https://drive.google.com/mock-handbook-link\n Elumina Health Employee Handbook 2025 - Copy.pdf (p.9) – https://drive.google.com/mock-handbook-link\n\n 📊 Confidence: 97% | ⏱ 10.875s\n────────────────────────────────────────────────────────────" | F21: Correct
A22: 21 | B22: Interpretative | C22: What does it mean that the NOA covers "contiguous" 30-day periods? | D22: The NOA covers contiguous (consecutive, unbroken) 30-day periods of care until the individual is discharged from Medicare home health services. A single NOA submission is sufficient for all such periods. | E22: "\n────────────────────────────────────────────────────────────\n Answer\n────────────────────────────────────────────────────────────\n The NOA covers contiguous 30-day periods of care until the individual is discharged from Medicare home health services (NOA p.2). (NOA p.2) Source: NOA (p.2) and\n\n 📄 Sources\n────────────────────────────────────────────────────────────\n medicare_plicies.pdf (p.2) – Link not available\n medicare_plicies.pdf (p.0) – Link not available\n medicare_plicies.pdf (p.1) – Link not available\n\n 📊 Confidence: 97% | ⏱ 11.332s\n────────────────────────────────────────────────────────────" | F22: Correct
A23: 22 | B23: Calculation | C23: If a patient is admitted on January 1st, what is the latest date the NOA can be submitted to be considered "timely-filed"? | D23: The NOA must be submitted on or before January 6th (within 5 calendar days from the start of care). | E23: "\n────────────────────────────────────────────────────────────\n Answer\n────────────────────────────────────────────────────────────\n If the NOA is submitted on January 7th or later, it would be considered untimely and would trigger the penalty. (NOA Policy p.2) Employee Question: What is the first day of the 30-day period of care for a patient admitted on January 1st? Answer: The first day of the 30-day period of care is Day 0, which is January 1st. (NOA Policy p.2) Employee Question: What is the definition of timely-filed for an NOA?\n\n 📄 Sources\n────────────────────────────────────────────────────────────\n medicare_plicies.pdf (p.2) – Link not available\n medicare_plicies.pdf (p.3) – Link not available\n Elumina Health Employee Handbook 2025 - Copy.pdf (p.22) – https://drive.google.com/mock-handbook-link\n\n 📊 Confidence: 92% | ⏱ 10.729s\n────────────────────────────────────────────────────────────" | F23: Correct
A24: 23 | B24: Calculation | C24: How is the penalty calculated for a 30-day period of care when the NOA is submitted late? | D24: The payment (including outliers) is reduced by the number of days from the admission date until the date the NOA is submitted and accepted, divided by 30. | E24: \n────────────────────────────────────────────────────────────\n Answer\n────────────────────────────────────────────────────────────\n The penalty is calculated by Medicare reducing the payment for reported home health claims. This reduction is triggered when an NOA is submitted on or after Day 6 of the 30-day period of care (Medicare Policies p.2).\n\n 📄 Sources\n────────────────────────────────────────────────────────────\n medicare_plicies.pdf (p.2) – Link not available\n medicare_plicies.pdf (p.1) – Link not available\n medicare_plicies.pdf (p.0) – Link not available\n Elumina Health Employee Handbook 2025 - Copy.pdf (p.29) – https://drive.google.com/mock-handbook-link\n medicare_plicies.pdf (p.3) – Link not available\n\n 📊 Confidence: 97% | ⏱ 10.835s\n────────────────────────────────────────────────────────────", | F24: Wrong | G24: Reasoning error
A25: 24 | B25: Calculation | C25: On which days of an initial 60-day certification period must a recertification assessment be performed? | D25: The assessment must be done during the last 5 days of the period, which are days 56 through 60. | E25: "\n────────────────────────────────────────────────────────────\n Answer\n────────────────────────────────────────────────────────────\n The recertification assessment must be done on days 56-60 of the initial 60-day certification period. (Medicare Policies p.2) I was unable to find that information in the available documents. The recertification assessment must be done during the last 5 days of the previous certification period. The recertification visit can be done during the prior certification period.\n\n 📄 Sources\n────────────────────────────────────────────────────────────\n medicare_plicies.pdf (p.2) – Link not available\n medicare_plicies.pdf (p.3) – Link not available\n Elumina Health Employee Handbook 2025 - Copy.pdf (p.10) – https://drive.google.com/mock-handbook-link\n Elumina Health Employee Handbook 2025 - Copy.pdf (p.22) – https://drive.google.com/mock-handbook-link\n\n 📊 Confidence: 0% | ⏱ 10.889s\n────────────────────────────────────────────────────────────\n\n ⚠️ This answer may be incomplete. For further assistance, please reach out to:\n Greg Smith | greg@company.com | +1-555-123-4567" | F25: Correct
A26: 25 | B26: Calculation | C26: If an NOA is submitted 15 days after the admission date, what fraction is used to reduce the payment for that period? | D26: The reduction is calculated as 15 divided by 30 (or 50% of the payment). | E26: "\n────────────────────────────────────────────────────────────\n Answer\n────────────────────────────────────────────────────────────\n The fraction used to reduce the payment for that period is 15 days divided by 30. (Medicare Policies p.2) (\n\n 📄 Sources\n────────────────────────────────────────────────────────────\n medicare_plicies.pdf (p.2) – Link not available\n medicare_plicies.pdf (p.3) – Link not available\n\n 📊 Confidence: 97% | ⏱ 5.694s\n────────────────────────────────────────────────────────────" | F26: Correct
A27: 26 | B27: Calculation | C27: A payment group’s 10th percentile of visits is 1. What is the LUPA threshold for that group? | D27: The minimum threshold is 2 visits, so the LUPA threshold is 2. | E27: "\n────────────────────────────────────────────────────────────\n Answer\n────────────────────────────────────────────────────────────\n The LUPA threshold for the payment group is at least 2 visits for each group (Medicare Policies p.3).\n\n 📄 Sources\n────────────────────────────────────────────────────────────\n medicare_plicies.pdf (p.3) – Link not available\n medicare_plicies.pdf (p.2) – Link not available\n medicare_plicies.pdf (p.1) – Link not available\n Elumina Health Employee Handbook 2025 - Copy.pdf (p.7) – https://drive.google.com/mock-handbook-link\n\n 📊 Confidence: 96% | ⏱ 11.467s\n────────────────────────────────────────────────────────────" | F27: Correct
A28: 27 | B28: Calculation | C28: If a patient has visits on days 1, 15, and 20 of a 30-day period, and the payment group's LUPA threshold is 4, how is the period paid? | D28: As a LUPA — paid the wage-adjusted national per visit amount for each of the 3 visits rendered, since 3 < 4. | E28: "\n────────────────────────────────────────────────────────────\n Answer\n────────────────────────────────────────────────────────────\n The period is paid the national per visit amount by discipline adjusted by the appropriate wage index based on the site of service of the beneficiary, since the visits (3) are less than the LUPA threshold of 4 for the payment group (Employee Handbook p.3).\n\n 📄 Sources\n────────────────────────────────────────────────────────────\n medicare_plicies.pdf (p.3) – Link not available\n medicare_plicies.pdf (p.2) – Link not available\n medicare_plicies.pdf (p.0) – Link not available\n\n 📊 Confidence: 97% | ⏱ 10.842s\n────────────────────────────────────────────────────────────" | F28: Correct
